2018-10-16 01:32:16,340 ERROR: Exception on / [GET] [in /Users/USER/PycharmProjects/flaskstructure/venv/lib/python3.7/site-packages/flask/app.py:1761]
Traceback (most recent call last):
  File "/Users/USER/PycharmProjects/flaskstructure/venv/lib/python3.7/site-packages/flask/app.py", line 2292, in wsgi_app
    response = self.full_dispatch_request()
  File "/Users/USER/PycharmProjects/flaskstructure/venv/lib/python3.7/site-packages/flask/app.py", line 1815, in full_dispatch_request
    rv = self.handle_user_exception(e)
  File "/Users/USER/PycharmProjects/flaskstructure/venv/lib/python3.7/site-packages/flask/app.py", line 1718, in handle_user_exception
    reraise(exc_type, exc_value, tb)
  File "/Users/USER/PycharmProjects/flaskstructure/venv/lib/python3.7/site-packages/flask/_compat.py", line 35, in reraise
    raise value
  File "/Users/USER/PycharmProjects/flaskstructure/venv/lib/python3.7/site-packages/flask/app.py", line 1813, in full_dispatch_request
    rv = self.dispatch_request()
  File "/Users/USER/PycharmProjects/flaskstructure/venv/lib/python3.7/site-packages/flask/app.py", line 1799, in dispatch_request
    return self.view_functions[rule.endpoint](**req.view_args)
  File "/Users/USER/PycharmProjects/flaskstructure/venv/lib/python3.7/site-packages/flask_login/utils.py", line 261, in decorated_view
    return func(*args, **kwargs)
  File "/Users/USER/PycharmProjects/flaskstructure/myData/main/routes.py", line 32, in index
    if posts.has_next else None
  File "/Users/USER/PycharmProjects/flaskstructure/venv/lib/python3.7/site-packages/flask/helpers.py", line 356, in url_for
    return appctx.app.handle_url_build_error(error, endpoint, values)
  File "/Users/USER/PycharmProjects/flaskstructure/venv/lib/python3.7/site-packages/flask/app.py", line 2061, in handle_url_build_error
    reraise(exc_type, exc_value, tb)
  File "/Users/USER/PycharmProjects/flaskstructure/venv/lib/python3.7/site-packages/flask/_compat.py", line 35, in reraise
    raise value
  File "/Users/USER/PycharmProjects/flaskstructure/venv/lib/python3.7/site-packages/flask/helpers.py", line 345, in url_for
    force_external=external)
  File "/Users/USER/PycharmProjects/flaskstructure/venv/lib/python3.7/site-packages/werkzeug/routing.py", line 1776, in build
    raise BuildError(endpoint, values, method, self)
werkzeug.routing.BuildError: Could not build url for endpoint 'index' with values ['page']. Did you mean 'main.index' instead?
2018-10-16 01:47:22,144 INFO: Myblog startup [in /Users/USER/PycharmProjects/flaskstructure/myData/__init__.py:68]
2018-10-16 12:50:44,885 INFO: Myblog startup [in /Users/USER/PycharmProjects/flaskstructure/myData/__init__.py:68]
2018-10-16 13:41:18,840 INFO: Myblog startup [in /Users/USER/PycharmProjects/flaskstructure/myData/__init__.py:68]
2018-10-16 14:15:43,328 INFO: Myblog startup [in /Users/USER/PycharmProjects/flaskstructure/myData/__init__.py:68]
2018-10-16 14:17:21,338 INFO: Myblog startup [in /Users/USER/PycharmProjects/flaskstructure/myData/__init__.py:68]
